{"content": {"suites": {"0": {"status": {"total_pass": 3, "total_skip": 0, "total_xpass": 0, "total_xfail": 0, "total_rerun": 0, "total_fail": 0, "total_error": 0}, "tests": {"0": {"status": "PASS", "message": "", "test_name": "test_File_Barcode_Type_Normal_Success", "rerun": "0"}, "1": {"status": "PASS", "message": "", "test_name": "test_File_Barcode_Type_Tester_Success", "rerun": "0"}, "2": {"status": "PASS", "message": "", "test_name": "test_File_Sku_Type_Normal_Success", "rerun": "0"}}, "suite_name": "src/SPECS/Script_Test_CreateQuotation/Test_create_quotation_xslx.py"}, "1": {"suite_name": "src/SPECS/test_login_csv.py", "tests": {"0": {"status": "FAIL", "message": "           ConnectionRefusedError: [WinError 10061] No connection could be made because the target machine actively refused it\n       urllib3.exceptions.NewConnectionError: <urllib3.connection.HTTPConnection object at 0x0000012C5CEC70E0>: Failed to establish a new connection: [WinError 10061] No connection could be made because the target machine actively refused it\n       urllib3.exceptions.MaxRetryError: HTTPConnectionPool(host='localhost', port=50946): Max retries exceeded with url: /session/fd2c9dfbac5d95bb46acbd6c76807ef5/element (Caused by NewConnectionError('<urllib3.connection.HTTPConnection object at 0x0000012C5CEC70E0>: Failed to establish a new connection: [WinError 10061] No connection could be made because the target machine actively refused it'))\n", "test_name": "test_login_file", "rerun": "0"}}, "status": {"total_pass": 0, "total_skip": 0, "total_xpass": 0, "total_xfail": 0, "total_rerun": 0, "total_fail": 1, "total_error": 0}}}}, "date": "July 01, 2024", "start_time": 1719799876.3998542, "total_suite": 2, "status": "FAIL", "status_list": {"pass": "3", "fail": "1", "skip": "0", "error": "0", "xpass": "0", "xfail": "0", "rerun": "0"}, "total_tests": "4"}